Workbook

Sheet API목록
B1: AI
B3: 구분 | C3: 도메인 | D3: API ID | E3: API 명 | F3: METHOD | G3: DATATYPE | H3: URL | I3: 상세
B4: 1 | C4: HNS | D4: ="HNS_AI_0"&B4 -> HNS_AI_01 | E4: 디바이스 S/W 모듈 버전 조회 | F4: GET | G4: JSON | H4: /v2/ai/geVersion | I4: 디바이스 S/W 모듈 버전 정보 (home.id == device.home, device.ipaddr == version.device && heartbeat.notice 메시지)
B5: 2 | C5: HNS | D5: =C5&"_AI_0"&B5 -> HNS_AI_02 | E5: 지능형 조명 제어 | F5: POST | G5: JSON | H5: /v2/ai/icmd/control/remoteAccessSmartlight | I5: 스마트분전반의 조명 상태를 외부에서 제어 (action = "control" | "mode_control")
B6: 3 | C6: HNS | D6: ="HNS_AI_0"&B6 -> HNS_AI_03 | E6: 지능형 조명 상태 조회2 | F6: GET | G6: JSON | H6: /v2/ai/icmd/control/remoteAccessSmartlight | I6: 스마트분전반의 조명 상태를 외부에서 조회
B7: 4 | C7: HNS | D7: =C7&"_AI_0"&B7 -> HNS_AI_04 | E7: 지능형 조명 상태 조회 | F7: GET | G7: JSON | H7: /v2/ai/icmd/status/smartDspInfo | I7: 월패드에게 스마트분전반의 상태를 요청
B8: 5 | C8: HNS | D8: ="HNS_AI_0"&B8 -> HNS_AI_05 | E8: 지능형 조명 Trend 동작 조회 | F8: GET | G8: JSON | H8: /v2/ai/trend | I8: 지능형 조명 상태 (imap/smart_light_info.reply 참고)
B9: 6 | C9: HNS | D9: =C9&"_AI_0"&B9 -> HNS_AI_06 | E9: 일괄소등제어기 제어 | F9: POST | G9: JSON | H9: /v2/ai/icmd/control/remoteAccessLightBatchControl | I9: 일괄소등제어기 상태를 외부에서 제어 (action = "control")
B10: 7 | C10: HNS | D10: ="HNS_AI_0"&B10 -> HNS_AI_07 | E10: 일괄소등제어기 상태 조회 | F10: GET | G10: JSON | H10: /v2/ai/icmd/status/remoteAccessLightBatchControl | I10: 일괄소등제어기 상태를 외부에서 조회 (action = "status")
B11: 8 | C11: HNS | D11: =C11&"_AI_0"&B11 -> HNS_AI_08 | E11: 멀티스위치의 조명제어기 제어 | F11: POST | G11: JSON | H11: /v2/ai/icmd/control/remoteAccessLight | I11: 멀티스위치의 조명제어기 상태를 외부에서 제어 (action = "control")
B12: 9 | C12: HNS | D12: ="HNS_AI_0"&B12 -> HNS_AI_09 | E12: 멀티스위치의 조명제어기 상태 조회 | F12: GET | G12: JSON | H12: /v2/ai/icmd/status/remoteAccessLight | I12: 멀티스위치의 조명제어기 상태를 외부에서 조회 (action = "status")
B13: 10 | C13: HNS | D13: =C13&"_AI_0"&B13 -> HNS_AI_010 | E13: 거실 조명제어기 제어 | F13: POST | G13: JSON | H13: /v2/ai/icmd/control/remoteAccessLivinglight | I13: 거실 조명제어기 상태를 외부에서 제어 (action = "control")
B14: 11 | C14: HNS | D14: ="HNS_AI_0"&B14 -> HNS_AI_011 | E14: 거실 조명제어기 상태 조회 | F14: GET | G14: JSON | H14: /v2/ai/icmd/status/remoteAccessLivinglight | I14: 거실 조명제어기 상태를 외부에서 조회 (action = "status")
B15: 12 | C15: HNS | D15: =C15&"_AI_0"&B15 -> HNS_AI_012 | E15: 난방 온도 조절기 제어 | F15: POST | G15: JSON | H15: /v2/ai/icmd/control/remoteAccessTemper | I15: 온도조절기 상태를 외부에서 제어 (action = "control")
B16: 13 | C16: HNS | D16: ="HNS_AI_0"&B16 -> HNS_AI_013 | E16: 난방 온도 조절기 상태 조회 | F16: GET | G16: JSON | H16: /v2/ai/icmd/status/remoteAccessTemper | I16: 온도조절기 상태를 외부에서 조회 (action = "status")
B17: 14 | C17: HNS | D17: =C17&"_AI_0"&B17 -> HNS_AI_014 | E17: 환기 제어 | F17: POST | G17: JSON | H17: /v2/ai/icmd/control/remoteAccessVentil | I17: 환기시스템 상태를 외부에서 제어 (action = "control", unit_cnt = 1, unit_num = "ventil")
B18: 15 | C18: HNS | D18: ="HNS_AI_0"&B18 -> HNS_AI_015 | E18: 환기 상태 조회 | F18: GET | G18: JSON | H18: /v2/ai/icmd/status/remoteAccessVentil | I18: 환기시스템 상태를 외부에서 조회 (action = "status", unit_num = "ventil")
B19: 16 | C19: HNS | D19: =C19&"_AI_0"&B19 -> HNS_AI_016 | E19: 에어컨 제어 | F19: POST | G19: JSON | H19: /v2/ai/icmd/control/remoteAccessSysaircon | I19: 시스템에어컨 상태를 외부에서 제어 (action = "control")
B20: 17 | C20: HNS | D20: ="HNS_AI_0"&B20 -> HNS_AI_017 | E20: 에어컨 상태 조회 | F20: GET | G20: JSON | H20: /v2/ai/icmd/status/remoteAccessSysaircon | I20: 시스템에어컨 상태를 외부에서 조회 (action = "status")
B21: 18 | C21: HNS | D21: =C21&"_AI_0"&B21 -> HNS_AI_018 | E21: 가스밸브 제어 | F21: POST | G21: JSON | H21: /v2/ai/icmd/control/remoteAccessGas | I21: 가스차단기 상태를 외부에서 제어 (action = "control")
B22: 19 | C22: HNS | D22: ="HNS_AI_0"&B22 -> HNS_AI_019 | E22: 가스밸브 상태 조회 | F22: GET | G22: JSON | H22: /v2/ai/icmd/status/remoteAccessGas | I22: 가스차단기 상태를 외부에서 조회 (action = "status")
B23: 20 | C23: HNS | D23: =C23&"_AI_0"&B23 -> HNS_AI_020 | E23: 제어기기 상태 제어 | F23: POST | G23: JSON | H23: /v2/ai/icmd/action/remoteGetHomeTotalDevice | I23: 제어기기의 전체 상태를 외부에서 제어 (action = "action")
B24: 21 | C24: HNS | D24: ="HNS_AI_0"&B24 -> HNS_AI_021 | E24: 제어기기 상태 조회 | F24: GET | G24: JSON | H24: /v2/ai/icmd/status/remoteGetHomeTotalDevice | I24: 제어기기의 전체 상태를 외부에서 조회 (action = "status")
B25: 22 | C25: HNS | D25: =C25&"_AI_0"&B25 -> HNS_AI_022 | E25: 에너지 사용이상 점검(조회) | F25: GET | G25: JSON | H25: /v2/ai/imap/getMetering | I25: 단지서버에서 받은 사용량 정보로부터 사용이상을 확인 (프론트에서 확인)
B30: 25 | C30: HNS | D30: ="HNS_AI_0"&B30 -> HNS_AI_025 | E30: 에너지 | F30: GET | G30: JSON | H30: /v2/ai/meter/daily/energies | I30: 일간 에너지 검침 조회 (전체)
B31: 26 | C31: HNS | D31: =C31&"_AI_0"&B31 -> HNS_AI_026 | E31: 에너지 | F31: GET | G31: JSON | H31: /v2/ai/meter/daily/energies/{year} | I31: 일간 에너지 검침 조회 (년)
B32: 27 | C32: HNS | D32: ="HNS_AI_0"&B32 -> HNS_AI_027 | E32: 에너지 | F32: GET | G32: JSON | H32: /v2/ai/meter/daily/energies/{year}/{month} | I32: 일간 에너지 검침 조회 (월)
B33: 28 | C33: HNS | D33: =C33&"_AI_0"&B33 -> HNS_AI_028 | E33: 에너지 | F33: GET | G33: JSON | H33: /v2/ai/meter/daily/energies/{year}/{month}/{day} | I33: 일간 에너지 검침 조회 (일)
B34: 29 | C34: HNS | D34: ="HNS_AI_0"&B34 -> HNS_AI_029 | E34: 에너지 | F34: GET | G34: JSON | H34: /v2/ai/meter/monthly/energies | I34: 월간 에너지 검침 조회 (전체)
B35: 30 | C35: HNS | D35: =C35&"_AI_0"&B35 -> HNS_AI_030 | E35: 에너지 | F35: GET | G35: JSON | H35: /v2/ai/meter/monthly/energies/{year} | I35: 월간 에너지 검침 조회 (년)
B36: 31 | C36: HNS | D36: ="HNS_AI_0"&B36 -> HNS_AI_031 | E36: 에너지 | F36: GET | G36: JSON | H36: /v2/ai/meter/monthly/energies/{year}/{month} | I36: 월간 에너지 검침 조회 (월)
B37: 32 | C37: HNS | D37: =C37&"_AI_0"&B37 -> HNS_AI_032 | E37: 엘리베이터 | F37: POST | G37: JSON | H37: /v2/ai/elevator/{dir} | I37: 엘리베이터 호출 (up/down)
B38: 33 | C38: HNS | D38: ="HNS_AI_0"&B38 -> HNS_AI_033 | E38: 공지사항 | F38: GET | G38: JSON | H38: /v2/ai/announcements | I38: 공지사항 목록 조회
B39: 34 | C39: HNS | D39: =C39&"_AI_0"&B39 -> HNS_AI_034 | E39: 공지사항 | F39: GET | G39: JSON | H39: /v2/ai/announcements/{id} | I39: 공지사항 상세 조회
B40: 35 | C40: HNS | D40: ="HNS_AI_0"&B40 -> HNS_AI_035 | E40: 차량 | F40: GET | G40: JSON | H40: /v2/ai/cars | I40: 입차목록 조회 (세대)
B41: 36 | C41: HNS | D41: =C41&"_AI_0"&B41 -> HNS_AI_036 | E41: 차량 | F41: GET | G41: JSON | H41: /v2/ai/cars/parkinfo | I41: 주차 정보 조회
B42: 37 | C42: HNS | D42: ="HNS_AI_0"&B42 -> HNS_AI_037 | E42: 차량 | F42: GET | G42: JSON | H42: /v2/ai/cars/guest | I42: 방문차량 조회
B43: 38 | C43: HNS | D43: =C43&"_AI_0"&B43 -> HNS_AI_038 | E43: 차량 | F43: POST | G43: JSON | H43: /v2/ai/cars/guest | I43: 방문 차량 등록/삭제
B44: 39 | C44: HNS | D44: ="HNS_AI_0"&B44 -> HNS_AI_039 | E44: 전기차 | F44: GET | G44: JSON | H44: /v2/ai/eleccar/charging_info | I44: 전기차 충전 정보 조회
B45: 40 | C45: HNS | D45: =C45&"_AI_0"&B45 -> HNS_AI_040 | E45: 전기차 | F45: GET | G45: JSON | H45: /v2/ai/eleccar/charger_info/{loc} | I45: 전기차 충전기 상태 조회 (위치별)
...

Sheet API 규격(제어기기)
B2: =API목록!E4&" ["&API목록!D4&"]" -> 디바이스 S/W 모듈 버전 조회 [HNS_AI_01]
A3: 1Depth | B3: 설명
A4: 2Depth | B4: API ID | C4: =API목록!D4 -> HNS_AI_01
A5: 3Depth | B5: API 명 | C5: =API목록!E4 -> 디바이스 S/W 모듈 버전 조회
B6: Data Type | C6: =API목록!G4 -> JSON
B7: Method | C7: =API목록!F4 -> GET
B8: API 설명 | C8: =API목록!I4 -> 디바이스 S/W 모듈 버전 정보 (home.id == device.home, device.ipaddr == version.device && heartbeat.notice 메시지)
B9: URL | C9: =API목록!H4 -> /v2/ai/geVersion
B10: Request Parameter
B11: 필드명 | C11: 파라미터명 | D11: Data Type | E11: 자리수 | F11: 필수여부 | G11: 암호화여부 | H11: 설명 | I11: 비고
B12: 동 정보 | C12: dongCode | D12: String | I12: home.dong_code
B13: 호 정보 | C13: homeCode | D13: String | I13: home.home_code
B14: 디바이스 종류 | C14: type | D14: int[] | I14: device.type ('0: 로비폰, 1: 경비실기, 2: 세대기(월패드))
B15: S/W 종류 | C15: module | D15: String[] | I15: version.module (app | moip | bsp | setting …)
B16: 진행 단계 | C16: state | D16: String[] | H16: {"ADDED", "STAGED", "UPGRADING", "UPGRADED"}
B17: 업데이트 파일명 | C17: filename | D17: String
B18: DB 버전 | C18: dbVer | D18: String
B19: 기기버전 | C19: devVer | D19: String
B21: Response Parameter
B22: 필드명 | C22: 파라미터명 | D22: Data Type | E22: 자리수 | F22: 필수여부 | G22: 암호화여부 | H22: 설명 | I22: 비고
B23: 코드 | C23: code | D23: String | F23: Y | H23: 결과 코드
B24: 메시지 | C24: message | D24: String | F24: Y | H24: 결과 메시지
B25: 데이터 | C25: data | D25: Object[] | F25: Y | H25: 결과 데이터
B26: 동 정보 | C26: dongCode | D26: String | F26: Y | H26: 동 | I26: home.dong_code
B27: 호 정보 | C27: homeCode | D27: String | F27: Y | H27: 호 | I27: home.home_code
B28: S/W 종류 | C28: module | D28: String | F28: Y | I28: version.module
B29: 디바이스 종류 | C29: type | D29: int | F29: Y | I29: device.type ('0: 로비폰, 1: 경비실기, 2: 세대기(월패드))
B30: 진행단계 | C30: state | D30: String | F30: Y | I30: version.state (ADDED, STAGED, UPGRADING, UPGRADED)
B31: Network IP | C31: ipaddr | D31: String | F31: Y | I31: device.ipaddr
B32: DB 조회 버전 | C32: dbVer | D32: String | I32: version 테이블의 모듈 버전
B33: 세대기(heartbeat) 버전 | C33: devVer | D33: String | I33: heartbeat.notice 메시지의 모듈 버전
B34: 기기버전 | C34: version | D34: String | F34: Y | I34: version.version
B35: 기기명칭 | C35: name | D35: String | I35: device.name
B36: 생성일 | C36: createdAt | D36: String | F36: Y | I36: 'yyyy-MM-dd hh:mm:ss' 형태
B37: 갱신일 | C37: updatedAt | D37: String | I37: 'yyyy-MM-dd hh:mm:ss' 형태
B38: 파일명 | C38: filename | D38: String
B39: 제어(통신) 결과 | C39: result | D39: String | F39: Y | H39: "ok" | "fail" | I39: default: "ok"
B41: Request query Sample
B42: { "dongCode": "20 ~ 1", "homeCode": "10 ~ 1", "module": "moip", "type": 2, "state": "UPGRADED", "version": "1002.10.02.0 ~ 1" }
B43: Response JSON Data Sample(Success)
...

Sheet API 규격(모바일기능)
A1: 일간 에너지 검침 조회 (전체) [HNS_AI_25]
A2: 설명
A3: API ID | B3: HNS_AI_25
A4: API 명 | B4: 일간 에너지 검침 조회 (전체)
A5: Data Type | B5: JSON
A6: Method | B6: GET
A7: API 설명 | B7: 세대의 일간 에너지 검침 현황 전체 조회 (dong, ho로 세대 식별)
A8: URL | B8: /v2/ai/meter/daily/energies
A9: Request Parameter
A10: 필드명 | B10: 파라미터명 | C10: Data Type | D10: 위치 | E10: 필수여부 | F10: 암호화여부 | G10: 설명 | H10: 비고
A11: 동 정보 | B11: dong | C11: String | D11: Query | E11: Y | G11: 동 코드
A12: 호 정보 | B12: ho | C12: String | D12: Query | E12: Y | G12: 호 코드
A13: 조회 수 | B13: limit | C13: int | D13: Query | G13: 조회 수 (기본 0=전체)
A14: 시작 위치 | B14: skip | C14: int | D14: Query | G14: 시작 위치 (기본 0)
A15: Response Parameter
A16: 필드명 | B16: 파라미터명 | C16: Data Type | D16: 자리수 | E16: 필수여부 | F16: 암호화여부 | G16: 설명 | H16: 비고
A17: 검침년도 | B17: ENERGY_YEAR | C17: String | E17: Y | G17: 검침 년도
A18: 검침월 | B18: ENERGY_MONTH | C18: String | E18: Y | G18: 검침 월
A19: 검침일 | B19: ENERGY_DAY | C19: String | E19: Y | G19: 검침 일
A20: 전기 계량기 | B20: ENERGY_CNT01 | C20: float | G20: 전기 계량기 정보
A21: 수도 계량기 | B21: ENERGY_CNT02 | C21: float | G21: 수도 계량기 정보
A22: 가스 계량기 | B22: ENERGY_CNT03 | C22: float | G22: 가스 계량기 정보
A23: 온수 계량기 | B23: ENERGY_CNT04 | C23: float | G23: 온수 계량기 정보
A24: 난방 계량기 | B24: ENERGY_CNT05 | C24: float | G24: 난방 계량기 정보
A25: 기타 계량기 | B25: ENERGY_CNT06 | C25: float | G25: 기타(탄소) 계량기 정보
A26: 전기 사용량 | B26: ENERGY_USE01 | C26: float | E26: Y | G26: 전기 사용량 (kWh)
A27: 수도 사용량 | B27: ENERGY_USE02 | C27: float | E27: Y | G27: 수도 사용량 (㎥)
A28: 가스 사용량 | B28: ENERGY_USE03 | C28: float | E28: Y | G28: 가스 사용량 (㎥)
A29: 온수 사용량 | B29: ENERGY_USE04 | C29: float | E29: Y | G29: 온수 사용량 (㎥)
A30: 난방 사용량 | B30: ENERGY_USE05 | C30: float | E30: Y | G30: 난방 사용량 (Mcal)
A31: 기타 사용량 | B31: ENERGY_USE06 | C31: float | G31: 기타(탄소) 사용량
A32: 동평형 전기순위 | B32: PYE_RANK01 | C32: int | G32: 동 평형대 전기 사용량 순위
A33: 동평형 수도순위 | B33: PYE_RANK02 | C33: int | G33: 동 평형대 수도 사용량 순위
A34: 동평형 가스순위 | B34: PYE_RANK03 | C34: int | G34: 동 평형대 가스 사용량 순위
A35: 동평형 전기평균 | B35: PYE_AVG01 | C35: float | G35: 동 평형대 전기 평균 사용량
A36: 동평형 수도평균 | B36: PYE_AVG02 | C36: float | G36: 동 평형대 수도 평균 사용량
A37: 동평형 가스평균 | B37: PYE_AVG03 | C37: float | G37: 동 평형대 가스 평균 사용량
A38: 동평형 전기요금 | B38: PYE_CHARGE01 | C38: int | G38: 동 평형대 전기 평균 요금 (원)
A39: 단지내 전기순위 | B39: ALL_RANK01 | C39: int | G39: 단지 내 전기 사용량 순위
A40: 단지내 전기평균 | B40: ALL_AVG01 | C40: float | G40: 단지 내 전기 평균 사용량
...

Sheet 에러코드
B2: 에러코드 | C2: 상태코드 | D2: 메시지 | E2: 설명 | F2: 비고
B3: S0000 | C3: 200 | D3: 정상적으로 처리 되었습니다.
B4: E00400 | C4: 400 | D4: 잘못된 요청입니다. | E4: 요청값이 형태에 맞지않음 | F4: API Router에서 발생
B5: E00401 | C5: 401 | D5: 유효하지 않은 토큰입니다. | E5: 토큰과 채널이 유효하지 않음 | F5: API Router에서 발생
B6: E00403 | C6: 403 | D6: ApI 사용 권한이 없습니다. | E6: 토큰과 채널에 사용권한이 없음 | F6: API Router에서 발생
B7: E00500 | C7: 500 | D7: 내부서버에 오류가 발생했습니다. | E7: 내부서버 문제 발생
B8: E01000 | C8: 400 | D8: 분석할수 없는 내용입니다. | E8: NLP에서 분석 불가 및 확인할수 없는 의도
